package exceptions_article_first_part;

public class App36 {
    public static void main(String[] args) {
        try {
            System.err.print(" 0");
            if (true) {throw new RuntimeException();}
            System.err.print(" 1");
        } catch (RuntimeException e) {     // перехватили RuntimeException
            System.err.print(" 2");
            if (true) {throw new Error();} // но бросили Error
        }
        System.err.println(" 3");          // пропускаем - уже летит Error
    }
}
